<sdf version='1.7'>
  <world name='default'>
    <light name='sun' type='directional'>
      <cast_shadows>1</cast_shadows>
      <pose>0 0 10 0 -0 0</pose>
      <diffuse>0.8 0.8 0.8 1</diffuse>
      <specular>0.2 0.2 0.2 1</specular>
      <attenuation>
        <range>1000</range>
        <constant>0.9</constant>
        <linear>0.01</linear>
        <quadratic>0.001</quadratic>
      </attenuation>
      <direction>-0.5 0.1 -0.9</direction>
      <spot>
        <inner_angle>0</inner_angle>
        <outer_angle>0</outer_angle>
        <falloff>0</falloff>
      </spot>
    </light>
    <model name='ground_plane'>
      <static>1</static>
      <link name='link'>
        <collision name='collision'>
          <geometry>
            <plane>
              <normal>0 0 1</normal>
              <size>100 100</size>
            </plane>
          </geometry>
          <surface>
            <contact>
              <collide_bitmask>65535</collide_bitmask>
              <ode/>
            </contact>
            <friction>
              <ode>
                <mu>100</mu>
                <mu2>50</mu2>
              </ode>
              <torsional>
                <ode/>
              </torsional>
            </friction>
            <bounce/>
          </surface>
          <max_contacts>10</max_contacts>
        </collision>
        <visual name='visual'>
          <cast_shadows>0</cast_shadows>
          <geometry>
            <plane>
              <normal>0 0 1</normal>
              <size>100 100</size>
            </plane>
          </geometry>
          <material>
            <script>
              <uri>file://media/materials/scripts/gazebo.material</uri>
              <name>Gazebo/Grey</name>
            </script>
          </material>
        </visual>
        <self_collide>0</self_collide>
        <enable_wind>0</enable_wind>
        <kinematic>0</kinematic>
      </link>
    </model>
    <gravity>0 0 -9.8</gravity>
    <magnetic_field>6e-06 2.3e-05 -4.2e-05</magnetic_field>
    <atmosphere type='adiabatic'/>
    <physics type='ode'>
      <max_step_size>0.001</max_step_size>
      <real_time_factor>1</real_time_factor>
      <real_time_update_rate>1000</real_time_update_rate>
    </physics>
    <scene>
      <ambient>0.4 0.4 0.4 1</ambient>
      <background>0.7 0.7 0.7 1</background>
      <shadows>1</shadows>
    </scene>
    <wind/>
    <spherical_coordinates>
      <surface_model>EARTH_WGS84</surface_model>
      <latitude_deg>0</latitude_deg>
      <longitude_deg>0</longitude_deg>
      <elevation>0</elevation>
      <heading_deg>0</heading_deg>
    </spherical_coordinates>
    <model name='robot'>
      <joint name='j0' type='fixed'>
        <pose relative_to='__model__'>0 0 0 0 -0 0</pose>
        <parent>world</parent>
        <child>base_link</child>
      </joint>
      <link name='base_link'>
        <pose relative_to='j0'>0 0 0 0 -0 0</pose>
        <inertial>
          <pose>4e-05 0 0.041277 0 -0 0</pose>
          <mass>2.06651</mass>
          <inertia>
            <ixx>0.006011</ixx>
            <ixy>0</ixy>
            <ixz>-2e-06</ixz>
            <iyy>0.006018</iyy>
            <iyz>0</iyz>
            <izz>0.009572</izz>
          </inertia>
        </inertial>
        <collision name='base_link_collision'>
          <pose>0 0 0 0 -0 0</pose>
          <geometry>
            <mesh>
              <scale>0.001 0.001 0.001</scale>
              <uri>/home/shanoj/catkin_ws/src/cooking_robot/meshes/base_link.stl</uri>
            </mesh>
          </geometry>
          <surface>
            <contact>
              <ode/>
            </contact>
            <friction>
              <ode>
                <mu>0.2</mu>
                <mu2>0.2</mu2>
              </ode>
              <torsional>
                <ode/>
              </torsional>
            </friction>
            <bounce/>
          </surface>
          <max_contacts>10</max_contacts>
        </collision>
        <visual name='base_link_visual'>
          <pose>0 0 0 0 -0 0</pose>
          <geometry>
            <mesh>
              <scale>0.001 0.001 0.001</scale>
              <uri>/home/shanoj/catkin_ws/src/cooking_robot/meshes/base_link.stl</uri>
            </mesh>
          </geometry>
          <material>
            <script>
              <name>Gazebo/Silver</name>
              <uri>file://media/materials/scripts/gazebo.material</uri>
            </script>
          </material>
        </visual>
        <self_collide>1</self_collide>
        <gravity>1</gravity>
        <enable_wind>0</enable_wind>
        <kinematic>0</kinematic>
      </link>
      <joint name='joint_base' type='revolute'>
        <pose relative_to='base_link'>0 0 0.07 0 -0 0</pose>
        <parent>base_link</parent>
        <child>link1_1</child>
        <axis>
          <xyz>0 0 1</xyz>
          <limit>
            <lower>-1.571</lower>
            <upper>1.571</upper>
            <effort>100</effort>
            <velocity>100</velocity>
          </limit>
          <dynamics>
            <spring_reference>0</spring_reference>
            <spring_stiffness>0</spring_stiffness>
          </dynamics>
        </axis>
      </joint>
      <link name='link1_1'>
        <pose relative_to='joint_base'>0 0 0 0 -0 0</pose>
        <inertial>
          <pose>0.023064 0.001342 0.046898 0 -0 0</pose>
          <mass>5.74211</mass>
          <inertia>
            <ixx>0.009895</ixx>
            <ixy>-0.000482</ixy>
            <ixz>-0.005786</ixz>
            <iyy>0.017173</iyy>
            <iyz>-0.000382</iyz>
            <izz>0.013403</izz>
          </inertia>
        </inertial>
        <collision name='link1_1_collision'>
          <pose>0 0 -0.07 0 -0 0</pose>
          <geometry>
            <mesh>
              <scale>0.001 0.001 0.001</scale>
              <uri>/home/shanoj/catkin_ws/src/cooking_robot/meshes/link1_1.stl</uri>
            </mesh>
          </geometry>
          <surface>
            <contact>
              <ode/>
            </contact>
            <friction>
              <ode>
                <mu>0.2</mu>
                <mu2>0.2</mu2>
              </ode>
              <torsional>
                <ode/>
              </torsional>
            </friction>
            <bounce/>
          </surface>
          <max_contacts>10</max_contacts>
        </collision>
        <visual name='link1_1_visual'>
          <pose>0 0 -0.07 0 -0 0</pose>
          <geometry>
            <mesh>
              <scale>0.001 0.001 0.001</scale>
              <uri>/home/shanoj/catkin_ws/src/cooking_robot/meshes/link1_1.stl</uri>
            </mesh>
          </geometry>
          <material>
            <script>
              <name>Gazebo/Silver</name>
              <uri>file://media/materials/scripts/gazebo.material</uri>
            </script>
          </material>
        </visual>
        <self_collide>1</self_collide>
        <enable_wind>0</enable_wind>
        <kinematic>0</kinematic>
      </link>
      <joint name='joint_link_1' type='revolute'>
        <pose relative_to='link1_1'>0.09 0.015 0.1 0 -0 0</pose>
        <parent>link1_1</parent>
        <child>link2_1</child>
        <axis>
          <xyz>0 1 0</xyz>
          <limit>
            <lower>-2.42</lower>
            <upper>0.71</upper>
            <effort>100</effort>
            <velocity>100</velocity>
          </limit>
          <dynamics>
            <spring_reference>0</spring_reference>
            <spring_stiffness>0</spring_stiffness>
          </dynamics>
        </axis>
      </joint>
      <link name='link2_1'>
        <pose relative_to='joint_link_1'>0 0 0 0 -0 0</pose>
        <inertial>
          <pose>0.080461 0.032657 -0 0 -0 0</pose>
          <mass>4.34984</mass>
          <inertia>
            <ixx>0.002088</ixx>
            <ixy>0.000167</ixy>
            <ixz>0</ixz>
            <iyy>0.025024</iyy>
            <iyz>0</iyz>
            <izz>0.024204</izz>
          </inertia>
        </inertial>
        <collision name='link2_1_collision'>
          <pose>-0.09 -0.015 -0.17 0 -0 0</pose>
          <geometry>
            <mesh>
              <scale>0.001 0.001 0.001</scale>
              <uri>/home/shanoj/catkin_ws/src/cooking_robot/meshes/link2_1.stl</uri>
            </mesh>
          </geometry>
          <surface>
            <contact>
              <ode/>
            </contact>
            <friction>
              <ode>
                <mu>0.2</mu>
                <mu2>0.2</mu2>
              </ode>
              <torsional>
                <ode/>
              </torsional>
            </friction>
            <bounce/>
          </surface>
          <max_contacts>10</max_contacts>
        </collision>
        <visual name='link2_1_visual'>
          <pose>-0.09 -0.015 -0.17 0 -0 0</pose>
          <geometry>
            <mesh>
              <scale>0.001 0.001 0.001</scale>
              <uri>/home/shanoj/catkin_ws/src/cooking_robot/meshes/link2_1.stl</uri>
            </mesh>
          </geometry>
          <material>
            <script>
              <name>Gazebo/Silver</name>
              <uri>file://media/materials/scripts/gazebo.material</uri>
            </script>
          </material>
        </visual>
        <self_collide>1</self_collide>
        <enable_wind>0</enable_wind>
        <kinematic>0</kinematic>
      </link>
      <joint name='joint_link_2' type='revolute'>
        <pose relative_to='link2_1'>0.2 0.019 0 0 -0 0</pose>
        <parent>link2_1</parent>
        <child>link3-2_joint_1</child>
        <axis>
          <xyz>0 1 0</xyz>
          <limit>
            <lower>-1</lower>
            <upper>4</upper>
            <effort>100</effort>
            <velocity>100</velocity>
          </limit>
          <dynamics>
            <spring_reference>0</spring_reference>
            <spring_stiffness>0</spring_stiffness>
          </dynamics>
        </axis>
      </joint>
      <link name='link3-2_joint_1'>
        <pose relative_to='joint_link_2'>0 0 0 0 -0 0</pose>
        <inertial>
          <pose>-0 -0.04521 0.002952 0 -0 0</pose>
          <mass>0.489262</mass>
          <inertia>
            <ixx>0.0005</ixx>
            <ixy>0</ixy>
            <ixz>0</ixz>
            <iyy>0.000169</iyy>
            <iyz>2e-06</iyz>
            <izz>0.000447</izz>
          </inertia>
        </inertial>
        <collision name='link3-2_joint_1_collision'>
          <pose>-0.29 -0.034 -0.17 0 -0 0</pose>
          <geometry>
            <mesh>
              <scale>0.001 0.001 0.001</scale>
              <uri>/home/shanoj/catkin_ws/src/cooking_robot/meshes/link3-2_joint_1.stl</uri>
            </mesh>
          </geometry>
          <surface>
            <contact>
              <ode/>
            </contact>
            <friction>
              <ode>
                <mu>0.2</mu>
                <mu2>0.2</mu2>
              </ode>
              <torsional>
                <ode/>
              </torsional>
            </friction>
            <bounce/>
          </surface>
          <max_contacts>10</max_contacts>
        </collision>
        <visual name='link3-2_joint_1_visual'>
          <pose>-0.29 -0.034 -0.17 0 -0 0</pose>
          <geometry>
            <mesh>
              <scale>0.001 0.001 0.001</scale>
              <uri>/home/shanoj/catkin_ws/src/cooking_robot/meshes/link3-2_joint_1.stl</uri>
            </mesh>
          </geometry>
          <material>
            <script>
              <name>Gazebo/Silver</name>
              <uri>file://media/materials/scripts/gazebo.material</uri>
            </script>
          </material>
        </visual>
        <self_collide>1</self_collide>
        <enable_wind>0</enable_wind>
        <kinematic>0</kinematic>
      </link>
      <joint name='joint_link_3' type='revolute'>
        <pose relative_to='link3-2_joint_1'>0 -0.0475 0.025 0 -0 0</pose>
        <parent>link3-2_joint_1</parent>
        <child>link3_1</child>
        <axis>
          <xyz>0 0 -1</xyz>
          <limit>
            <lower>-1.571</lower>
            <upper>1.571</upper>
            <effort>100</effort>
            <velocity>100</velocity>
          </limit>
          <dynamics>
            <spring_reference>0</spring_reference>
            <spring_stiffness>0</spring_stiffness>
          </dynamics>
        </axis>
      </joint>
      <link name='link3_1'>
        <pose relative_to='joint_link_3'>0 0 0 0 -0 0</pose>
        <inertial>
          <pose>0 -0.000518 0.061529 0 -0 0</pose>
          <mass>1.24112</mass>
          <inertia>
            <ixx>0.002432</ixx>
            <ixy>0</ixy>
            <ixz>0</ixz>
            <iyy>0.001722</iyy>
            <iyz>3e-05</iyz>
            <izz>0.001103</izz>
          </inertia>
        </inertial>
        <collision name='link3_1_collision'>
          <pose>-0.29 0.0135 -0.195 0 -0 0</pose>
          <geometry>
            <mesh>
              <scale>0.001 0.001 0.001</scale>
              <uri>/home/shanoj/catkin_ws/src/cooking_robot/meshes/link3_1.stl</uri>
            </mesh>
          </geometry>
          <surface>
            <contact>
              <ode/>
            </contact>
            <friction>
              <ode>
                <mu>0.2</mu>
                <mu2>0.2</mu2>
              </ode>
              <torsional>
                <ode/>
              </torsional>
            </friction>
            <bounce/>
          </surface>
          <max_contacts>10</max_contacts>
        </collision>
        <visual name='link3_1_visual'>
          <pose>-0.29 0.0135 -0.195 0 -0 0</pose>
          <geometry>
            <mesh>
              <scale>0.001 0.001 0.001</scale>
              <uri>/home/shanoj/catkin_ws/src/cooking_robot/meshes/link3_1.stl</uri>
            </mesh>
          </geometry>
          <material>
            <script>
              <name>Gazebo/Silver</name>
              <uri>file://media/materials/scripts/gazebo.material</uri>
            </script>
          </material>
        </visual>
        <self_collide>1</self_collide>
        <enable_wind>0</enable_wind>
        <kinematic>0</kinematic>
      </link>
      <joint name='joint_link_4' type='revolute'>
        <pose relative_to='link3_1'>0 -0.046 0.1175 0 -0 0</pose>
        <parent>link3_1</parent>
        <child>gripper_joint1_1</child>
        <axis>
          <xyz>0 1 0</xyz>
          <limit>
            <lower>-1.571</lower>
            <upper>1.571</upper>
            <effort>100</effort>
            <velocity>100</velocity>
          </limit>
          <dynamics>
            <spring_reference>0</spring_reference>
            <spring_stiffness>0</spring_stiffness>
          </dynamics>
        </axis>
      </joint>
      <link name='gripper_joint1_1'>
        <pose relative_to='joint_link_4'>0 0 0 0 -0 0</pose>
        <inertial>
          <pose>-0 0.04521 0.002952 0 -0 0</pose>
          <mass>0.489259</mass>
          <inertia>
            <ixx>0.0005</ixx>
            <ixy>0</ixy>
            <ixz>0</ixz>
            <iyy>0.000169</iyy>
            <iyz>-2e-06</iyz>
            <izz>0.000447</izz>
          </inertia>
        </inertial>
        <collision name='gripper_joint1_1_collision'>
          <pose>-0.29 0.0595 -0.3125 0 -0 0</pose>
          <geometry>
            <mesh>
              <scale>0.001 0.001 0.001</scale>
              <uri>/home/shanoj/catkin_ws/src/cooking_robot/meshes/gripper_joint1_1.stl</uri>
            </mesh>
          </geometry>
          <surface>
            <contact>
              <ode/>
            </contact>
            <friction>
              <ode>
                <mu>0.2</mu>
                <mu2>0.2</mu2>
              </ode>
              <torsional>
                <ode/>
              </torsional>
            </friction>
            <bounce/>
          </surface>
          <max_contacts>10</max_contacts>
        </collision>
        <visual name='gripper_joint1_1_visual'>
          <pose>-0.29 0.0595 -0.3125 0 -0 0</pose>
          <geometry>
            <mesh>
              <scale>0.001 0.001 0.001</scale>
              <uri>/home/shanoj/catkin_ws/src/cooking_robot/meshes/gripper_joint1_1.stl</uri>
            </mesh>
          </geometry>
          <material>
            <script>
              <name>Gazebo/Silver</name>
              <uri>file://media/materials/scripts/gazebo.material</uri>
            </script>
          </material>
        </visual>
        <self_collide>1</self_collide>
        <enable_wind>0</enable_wind>
        <kinematic>0</kinematic>
      </link>
      <joint name='joint_gripper' type='revolute'>
        <pose relative_to='gripper_joint1_1'>0 0.0475 0.025 0 -0 0</pose>
        <parent>gripper_joint1_1</parent>
        <child>link4_1</child>
        <axis>
          <xyz>0 0 -1</xyz>
          <limit>
            <lower>-1.571</lower>
            <upper>1.571</upper>
            <effort>100</effort>
            <velocity>100</velocity>
          </limit>
          <dynamics>
            <spring_reference>0</spring_reference>
            <spring_stiffness>0</spring_stiffness>
          </dynamics>
        </axis>
      </joint>
      <link name='link4_1'>
        <pose relative_to='joint_gripper'>0 0 0 0 -0 0</pose>
        <inertial>
          <pose>0.000184 0.000271 0.02551 0 -0 0</pose>
          <mass>0.680195</mass>
          <inertia>
            <ixx>0.000469</ixx>
            <ixy>0</ixy>
            <ixz>0</ixz>
            <iyy>0.000457</iyy>
            <iyz>0</iyz>
            <izz>0.000272</izz>
          </inertia>
        </inertial>
        <collision name='link4_1_collision'>
          <pose>-0.29 0.012 -0.3375 0 -0 0</pose>
          <geometry>
            <mesh>
              <scale>0.001 0.001 0.001</scale>
              <uri>/home/shanoj/catkin_ws/src/cooking_robot/meshes/link4_1.stl</uri>
            </mesh>
          </geometry>
          <surface>
            <contact>
              <ode/>
            </contact>
            <friction>
              <ode>
                <mu>0.2</mu>
                <mu2>0.2</mu2>
              </ode>
              <torsional>
                <ode/>
              </torsional>
            </friction>
            <bounce/>
          </surface>
          <max_contacts>10</max_contacts>
        </collision>
        <visual name='link4_1_visual'>
          <pose>-0.29 0.012 -0.3375 0 -0 0</pose>
          <geometry>
            <mesh>
              <scale>0.001 0.001 0.001</scale>
              <uri>/home/shanoj/catkin_ws/src/cooking_robot/meshes/link4_1.stl</uri>
            </mesh>
          </geometry>
          <material>
            <script>
              <name>Gazebo/Silver</name>
              <uri>file://media/materials/scripts/gazebo.material</uri>
            </script>
          </material>
        </visual>
        <self_collide>1</self_collide>
        <enable_wind>0</enable_wind>
        <kinematic>0</kinematic>
      </link>
      <joint name='joint_gripper_left' type='revolute'>
        <pose relative_to='link4_1'>0.01018 0.013765 0.075 0 -0 0</pose>
        <parent>link4_1</parent>
        <child>Spur_Gear__24_teeth___1__1</child>
        <axis>
          <xyz>1 0 0</xyz>
          <limit>
            <lower>-0.68</lower>
            <upper>0</upper>
            <effort>100</effort>
            <velocity>100</velocity>
          </limit>
          <dynamics>
            <spring_reference>0</spring_reference>
            <spring_stiffness>0</spring_stiffness>
          </dynamics>
        </axis>
      </joint>
      <link name='Spur_Gear__24_teeth___1__1'>
        <pose relative_to='joint_gripper_left'>0 0 0 0 -0 0</pose>
        <inertial>
          <pose>-0.01 -0.002725 0.030042 0 -0 0</pose>
          <mass>0.196292</mass>
          <inertia>
            <ixx>0.000182</ixx>
            <ixy>0</ixy>
            <ixz>0</ixz>
            <iyy>0.000182</iyy>
            <iyz>1.9e-05</iyz>
            <izz>1.4e-05</izz>
          </inertia>
        </inertial>
        <collision name='Spur_Gear__24_teeth___1__1_collision'>
          <pose>-0.30018 -0.001765 -0.4125 0 -0 0</pose>
          <geometry>
            <mesh>
              <scale>0.001 0.001 0.001</scale>
              <uri>/home/shanoj/catkin_ws/src/cooking_robot/meshes/Spur_Gear__24_teeth___1__1.stl</uri>
            </mesh>
          </geometry>
          <surface>
            <contact>
              <ode/>
            </contact>
            <friction>
              <ode>
                <mu>0.2</mu>
                <mu2>0.2</mu2>
              </ode>
              <torsional>
                <ode/>
              </torsional>
            </friction>
            <bounce/>
          </surface>
          <max_contacts>10</max_contacts>
        </collision>
        <visual name='Spur_Gear__24_teeth___1__1_visual'>
          <pose>-0.30018 -0.001765 -0.4125 0 -0 0</pose>
          <geometry>
            <mesh>
              <scale>0.001 0.001 0.001</scale>
              <uri>/home/shanoj/catkin_ws/src/cooking_robot/meshes/Spur_Gear__24_teeth___1__1.stl</uri>
            </mesh>
          </geometry>
          <material>
            <script>
              <name>Gazebo/Silver</name>
              <uri>file://media/materials/scripts/gazebo.material</uri>
            </script>
          </material>
        </visual>
        <self_collide>1</self_collide>
        <enable_wind>0</enable_wind>
        <kinematic>0</kinematic>
      </link>
      <joint name='joint_gripper_right' type='revolute'>
        <pose relative_to='link4_1'>0.01018 -0.013235 0.075 0 -0 0</pose>
        <parent>link4_1</parent>
        <child>Spur_Gear__24_teeth__1</child>
        <axis>
          <xyz>1 0 0</xyz>
          <limit>
            <lower>0</lower>
            <upper>0.68</upper>
            <effort>100</effort>
            <velocity>100</velocity>
          </limit>
          <dynamics>
            <spring_reference>0</spring_reference>
            <spring_stiffness>0</spring_stiffness>
          </dynamics>
        </axis>
      </joint>
      <link name='Spur_Gear__24_teeth__1'>
        <pose relative_to='joint_gripper_right'>0 0 0 0 -0 0</pose>
        <inertial>
          <pose>-0.01 0.002727 0.030108 0 -0 0</pose>
          <mass>0.196475</mass>
          <inertia>
            <ixx>0.000183</ixx>
            <ixy>0</ixy>
            <ixz>0</ixz>
            <iyy>0.000182</iyy>
            <iyz>-1.9e-05</iyz>
            <izz>1.4e-05</izz>
          </inertia>
        </inertial>
        <collision name='Spur_Gear__24_teeth__1_collision'>
          <pose>-0.30018 0.025235 -0.4125 0 -0 0</pose>
          <geometry>
            <mesh>
              <scale>0.001 0.001 0.001</scale>
              <uri>/home/shanoj/catkin_ws/src/cooking_robot/meshes/Spur_Gear__24_teeth__1.stl</uri>
            </mesh>
          </geometry>
          <surface>
            <contact>
              <ode/>
            </contact>
            <friction>
              <ode>
                <mu>0.2</mu>
                <mu2>0.2</mu2>
              </ode>
              <torsional>
                <ode/>
              </torsional>
            </friction>
            <bounce/>
          </surface>
          <max_contacts>10</max_contacts>
        </collision>
        <visual name='Spur_Gear__24_teeth__1_visual'>
          <pose>-0.30018 0.025235 -0.4125 0 -0 0</pose>
          <geometry>
            <mesh>
              <scale>0.001 0.001 0.001</scale>
              <uri>/home/shanoj/catkin_ws/src/cooking_robot/meshes/Spur_Gear__24_teeth__1.stl</uri>
            </mesh>
          </geometry>
          <material>
            <script>
              <name>Gazebo/Silver</name>
              <uri>file://media/materials/scripts/gazebo.material</uri>
            </script>
          </material>
        </visual>
        <self_collide>1</self_collide>
        <enable_wind>0</enable_wind>
        <kinematic>0</kinematic>
      </link>
      <static>0</static>
      <plugin name='control' filename='libgazebo_ros_control.so'>
        <robotNamespace>/</robotNamespace>
      </plugin>
      <pose>0 0 0 0 -0 0</pose>
    </model>
    <state world_name='default'>
      <sim_time>434 385000000</sim_time>
      <real_time>441 355372314</real_time>
      <wall_time>1714121298 683283333</wall_time>
      <iterations>434385</iterations>
      <model name='ground_plane'>
        <pose>0 0 0 0 -0 0</pose>
        <scale>1 1 1</scale>
        <link name='link'>
          <pose>0 0 0 0 -0 0</pose>
          <velocity>0 0 0 0 -0 0</velocity>
          <acceleration>0 0 0 0 -0 0</acceleration>
          <wrench>0 0 0 0 -0 0</wrench>
        </link>
      </model>
      <model name='grrn_box'>
        <pose>0.262883 -0.012497 0.009084 0.000209 0.000985 -0.06911</pose>
        <scale>1 1 1</scale>
        <link name='link'>
          <pose>0.262883 -0.012497 0.009084 0.000209 0.000985 -0.06911</pose>
          <velocity>0 0 0 0 -0 0</velocity>
          <acceleration>-0.009598 0.00795 -0.032414 -0.879103 -1.06138 0</acceleration>
          <wrench>-0.009598 0.00795 -0.032414 0 -0 0</wrench>
        </link>
      </model>
      <model name='robot'>
        <pose>1e-06 0 1e-06 0 -7e-06 0</pose>
        <scale>1 1 1</scale>
        <link name='Spur_Gear__24_teeth__1'>
          <pose>0.209327 -0.026342 0.089198 -2.80151 -0.013661 -3.13629</pose>
          <velocity>0.000347 6e-06 -0.000517 0.000509 0.001331 0.000516</velocity>
          <acceleration>0.041372 -0.001652 -0.016761 0.142183 -0.296794 -0.285329</acceleration>
          <wrench>0.008129 -0.000325 -0.003293 0 -0 0</wrench>
        </link>
        <link name='Spur_Gear__24_teeth___1__1'>
          <pose>0.209184 0.000658 0.089194 2.80179 -0.013664 -3.1363</pose>
          <velocity>0.000331 7e-06 -0.000511 0.000216 0.001385 0.000489</velocity>
          <acceleration>0.036528 -0.001744 -0.011344 0.14634 -0.260387 0.328711</acceleration>
          <wrench>0.00717 -0.000342 -0.002227 0 -0 0</wrench>
        </link>
        <link name='base_link'>
          <pose>1e-06 0 1e-06 0 -7e-06 0</pose>
          <velocity>-2e-06 -2e-06 -1e-06 2.5e-05 0.000131 -1e-06</velocity>
          <acceleration>-0.021065 -0.003471 -0.018673 0.09601 -0.521871 -0.000879</acceleration>
          <wrench>-0.04353 -0.007174 -0.038588 0 -0 0</wrench>
        </link>
        <link name='gripper_joint1_1'>
          <pose>0.220694 -0.060534 0.189059 -3.14138 -0.01363 3.13933</pose>
          <velocity>0.000491 -9e-06 -0.000533 0.000143 0.001135 0.000408</velocity>
          <acceleration>0.00695 -0.019401 -0.007825 0.145266 -0.504936 0.046729</acceleration>
          <wrench>0.0034 -0.009492 -0.003829 0 -0 0</wrench>
        </link>
        <link name='link1_1'>
          <pose>1e-06 0 0.07 -5e-06 5.1e-05 -0.004678</pose>
          <velocity>1.3e-05 -3e-06 -5e-06 4.2e-05 0.000468 -6.1e-05</velocity>
          <acceleration>-0.030056 -0.008441 -0.01879 0.113615 -0.316888 -0.009174</acceleration>
          <wrench>-0.172584 -0.048469 -0.107892 0 -0 0</wrench>
        </link>
        <link name='link2_1'>
          <pose>0.090076 0.014579 0.169994 -1.2e-05 -0.935955 -0.00467</pose>
          <velocity>6.4e-05 -1.3e-05 -5e-05 5.7e-05 0.003684 -6.2e-05</velocity>
          <acceleration>-0.056714 -0.022586 0.009356 -0.062914 -0.207839 -0.115268</acceleration>
          <wrench>-0.246696 -0.098247 0.040698 0 -0 0</wrench>
        </link>
        <link name='link3-2_joint_1'>
          <pose>0.208774 0.033025 0.331024 -3.14158 0.086089 3.13692</pose>
          <velocity>0.000663 -2.9e-05 -0.000505 -1.7e-05 0.001063 -1.7e-05</velocity>
          <acceleration>-0.062654 -0.03222 0.002257 0.033989 -0.122502 0.02061</acceleration>
          <wrench>-0.030654 -0.015764 0.001104 0 -0 0</wrench>
        </link>
        <link name='link3_1'>
          <pose>0.210702 -0.014485 0.306116 -3.14136 0.086032 3.13935</pose>
          <velocity>0.000635 -2.6e-05 -0.000511 0.000104 0.001373 0.000417</velocity>
          <acceleration>-0.021838 -0.024997 -0.001684 0.08687 -0.46643 -0.001837</acceleration>
          <wrench>-0.027104 -0.031024 -0.00209 0 -0 0</wrench>
        </link>
        <link name='link4_1'>
          <pose>0.22046 -0.013039 0.16405 -3.14148 -0.013658 -3.1363</pose>
          <velocity>0.00044 -4e-06 -0.000528 0.000182 0.001319 0.000526</velocity>
          <acceleration>0.022588 -0.012719 -0.011099 0.136999 -0.281229 0.042804</acceleration>
          <wrench>0.015364 -0.008651 -0.00755 0 -0 0</wrench>
        </link>
      </model>
      <light name='sun'>
        <pose>0 0 10 0 -0 0</pose>
      </light>
    </state>
    <model name='grrn_box'>
      <link name='link'>
        <inertial>
          <mass>1</mass>
          <inertia>
            <ixx>0.166667</ixx>
            <ixy>0</ixy>
            <ixz>0</ixz>
            <iyy>0.166667</iyy>
            <iyz>0</iyz>
            <izz>0.166667</izz>
          </inertia>
          <pose>0 0 0 0 -0 0</pose>
        </inertial>
        <self_collide>0</self_collide>
        <enable_wind>0</enable_wind>
        <kinematic>0</kinematic>
        <pose>0 0 0 0 -0 0</pose>
        <gravity>1</gravity>
        <visual name='visual'>
          <geometry>
            <box>
              <size>0.038242 0.027447 0.018124</size>
            </box>
          </geometry>
          <material>
            <script>
              <name>Gazebo/Grey</name>
              <uri>file://media/materials/scripts/gazebo.material</uri>
            </script>
            <shader type='pixel'>
              <normal_map>__default__</normal_map>
            </shader>
            <ambient>0 1 0 0</ambient>
            <diffuse>0.7 0.7 0.7 1</diffuse>
            <specular>0.01 0.01 0.01 1</specular>
            <emissive>0 0 0 1</emissive>
          </material>
          <pose>0 0 0 0 -0 0</pose>
          <transparency>0</transparency>
          <cast_shadows>1</cast_shadows>
        </visual>
        <collision name='collision'>
          <laser_retro>0</laser_retro>
          <max_contacts>10</max_contacts>
          <pose>0 0 0 0 -0 0</pose>
          <geometry>
            <box>
              <size>0.038242 0.027447 0.018124</size>
            </box>
          </geometry>
          <surface>
            <friction>
              <ode>
                <mu>1</mu>
                <mu2>1</mu2>
                <fdir1>0 0 0</fdir1>
                <slip1>0</slip1>
                <slip2>0</slip2>
              </ode>
              <torsional>
                <coefficient>1</coefficient>
                <patch_radius>0</patch_radius>
                <surface_radius>0</surface_radius>
                <use_patch_radius>1</use_patch_radius>
                <ode>
                  <slip>0</slip>
                </ode>
              </torsional>
            </friction>
            <bounce>
              <restitution_coefficient>0</restitution_coefficient>
              <threshold>1e+06</threshold>
            </bounce>
            <contact>
              <collide_without_contact>0</collide_without_contact>
              <collide_without_contact_bitmask>1</collide_without_contact_bitmask>
              <collide_bitmask>1</collide_bitmask>
              <ode>
                <soft_cfm>0</soft_cfm>
                <soft_erp>0.2</soft_erp>
                <kp>1e+13</kp>
                <kd>1</kd>
                <max_vel>0.01</max_vel>
                <min_depth>0</min_depth>
              </ode>
              <bullet>
                <split_impulse>1</split_impulse>
                <split_impulse_penetration_threshold>-0.01</split_impulse_penetration_threshold>
                <soft_cfm>0</soft_cfm>
                <soft_erp>0.2</soft_erp>
                <kp>1e+13</kp>
                <kd>1</kd>
              </bullet>
            </contact>
          </surface>
        </collision>
      </link>
      <static>0</static>
      <allow_auto_disable>1</allow_auto_disable>
      <pose>0.233433 -0.013695 0.009075 -0.000918 2.2e-05 -0.000202</pose>
    </model>
    <gui fullscreen='0'>
      <camera name='user_camera'>
        <pose>0.749439 -0.131718 0.090803 0 0.111855 2.95592</pose>
        <view_controller>orbit</view_controller>
        <projection_type>perspective</projection_type>
      </camera>
    </gui>
  </world>
</sdf>
