<?xml version="1.0" ?>
<!-- =================================================================================== -->
<!-- |    This document was autogenerated by xacro from /home/shanoj/catkin_ws/src/cooking_robot/urdf/primary_manipulator.xacro | -->
<!-- |    EDITING THIS FILE BY HAND IS NOT RECOMMENDED                                 | -->
<!-- =================================================================================== -->
<robot name="primary_manipulator">
    <material name="silver">
        <color rgba="0.700 0.700 0.700 1.000" />
    </material>
    <transmission name="Revolute 57_tran">
        <type>transmission_interface/SimpleTransmission</type>
        <joint name="joint_base">
            <hardwareInterface>hardware_interface/PositionJointInterface</hardwareInterface>
        </joint>
        <actuator name="Revolute 57_actr">
            <hardwareInterface>hardware_interface/PositionJointInterface</hardwareInterface>
            <mechanicalReduction>1</mechanicalReduction>
        </actuator>
    </transmission>
    <transmission name="Revolute 58_tran">
        <type>transmission_interface/SimpleTransmission</type>
        <joint name="joint_link_1">
            <hardwareInterface>hardware_interface/PositionJointInterface</hardwareInterface>
        </joint>
        <actuator name="Revolute 58_actr">
            <hardwareInterface>hardware_interface/PositionJointInterface</hardwareInterface>
            <mechanicalReduction>1</mechanicalReduction>
        </actuator>
    </transmission>
    <transmission name="Revolute 59_tran">
        <type>transmission_interface/SimpleTransmission</type>
        <joint name="joint_link_2">
            <hardwareInterface>hardware_interface/PositionJointInterface</hardwareInterface>
        </joint>
        <actuator name="Revolute 59_actr">
            <hardwareInterface>hardware_interface/PositionJointInterface</hardwareInterface>
            <mechanicalReduction>1</mechanicalReduction>
        </actuator>
    </transmission>
    <transmission name="Revolute 60_tran">
        <type>transmission_interface/SimpleTransmission</type>
        <joint name="joint_link_3">
            <hardwareInterface>hardware_interface/PositionJointInterface</hardwareInterface>
        </joint>
        <actuator name="Revolute 60_actr">
            <hardwareInterface>hardware_interface/PositionJointInterface</hardwareInterface>
            <mechanicalReduction>1</mechanicalReduction>
        </actuator>
    </transmission>
    <transmission name="Revolute 61_tran">
        <type>transmission_interface/SimpleTransmission</type>
        <joint name="joint_link_4">
            <hardwareInterface>hardware_interface/PositionJointInterface</hardwareInterface>
        </joint>
        <actuator name="Revolute 61_actr">
            <hardwareInterface>hardware_interface/PositionJointInterface</hardwareInterface>
            <mechanicalReduction>1</mechanicalReduction>
        </actuator>
    </transmission>
    <transmission name="Revolute 62_tran">
        <type>transmission_interface/SimpleTransmission</type>
        <joint name="joint_gripper">
            <hardwareInterface>hardware_interface/PositionJointInterface</hardwareInterface>
        </joint>
        <actuator name="Revolute 62_actr">
            <hardwareInterface>hardware_interface/PositionJointInterface</hardwareInterface>
            <mechanicalReduction>1</mechanicalReduction>
        </actuator>
    </transmission>
    <transmission name="Revolute 63_tran">
        <type>transmission_interface/SimpleTransmission</type>
        <joint name="joint_gripper_left">
            <hardwareInterface>hardware_interface/EffortJointInterface</hardwareInterface>
        </joint>
        <actuator name="Revolute 63_actr">
            <hardwareInterface>hardware_interface/EffortJointInterface</hardwareInterface>
            <mechanicalReduction>1</mechanicalReduction>
        </actuator>
    </transmission>
    <transmission name="Revolute 64_tran">
        <type>transmission_interface/SimpleTransmission</type>
        <joint name="joint_gripper_right">
            <hardwareInterface>hardware_interface/EffortJointInterface</hardwareInterface>
        </joint>
        <actuator name="Revolute 64_actr">
            <hardwareInterface>hardware_interface/EffortJointInterface</hardwareInterface>
            <mechanicalReduction>1</mechanicalReduction>
        </actuator>
    </transmission>
    <gazebo>
        <plugin filename="libgazebo_ros_control.so" name="control" />
        <plugin name="gazebo_ros_control">
            <robotNamespace>/</robotNamespace>
        </plugin>
    </gazebo>
    <gazebo>
        <plugin name="gazebo_grasp_fix" filename="libgazebo_grasp_fix.so">
            <arm>
                <arm_name>arm</arm_name>
                <palm_link> link4_1 </palm_link>
                <gripper_link> Spur_Gear__24_teeth___1__1 </gripper_link>
                <gripper_link> Spur_Gear__24_teeth__1 </gripper_link>
                
            </arm>
            <forces_angle_tolerance>100</forces_angle_tolerance>
            <update_rate>10</update_rate>
            <grip_count_threshold>3</grip_count_threshold>
            <max_grip_count>10</max_grip_count>
            <release_tolerance>0.01</release_tolerance>
            <disable_collisions_on_attach>true</disable_collisions_on_attach>
            <contact_topic>__default_topic__</contact_topic>
        </plugin>
    </gazebo>   
    <gazebo reference="base_link">
        <material>Gazebo/Silver</material>
        <mu1>0.2</mu1>
        <mu2>0.2</mu2>
        <selfCollide>true</selfCollide>
        <gravity>true</gravity>
    </gazebo>
    <gazebo reference="link1_1">
        <material>Gazebo/Silver</material>
        <mu1>0.2</mu1>
        <mu2>0.2</mu2>
        <selfCollide>true</selfCollide>
    </gazebo>
    <gazebo reference="link2_1">
        <material>Gazebo/Silver</material>
        <mu1>0.2</mu1>
        <mu2>0.2</mu2>
        <selfCollide>true</selfCollide>
    </gazebo>
    <gazebo reference="link3-2_joint_1">
        <material>Gazebo/Silver</material>
        <mu1>0.2</mu1>
        <mu2>0.2</mu2>
        <selfCollide>true</selfCollide>
    </gazebo>
    <gazebo reference="link3_1">
        <material>Gazebo/Silver</material>
        <mu1>0.2</mu1>
        <mu2>0.2</mu2>
        <selfCollide>true</selfCollide>
    </gazebo>
    <gazebo reference="gripper_joint1_1">
        <material>Gazebo/Silver</material>
        <mu1>0.2</mu1>
        <mu2>0.2</mu2>
        <selfCollide>true</selfCollide>
    </gazebo>
    <gazebo reference="link4_1">
        <material>Gazebo/Silver</material>
        <mu1>0.2</mu1>
        <mu2>0.2</mu2>
        <selfCollide>true</selfCollide>
    </gazebo>
    <gazebo reference="Spur_Gear__24_teeth__1">
        <material>Gazebo/Silver</material>
        <mu1>0.2</mu1>
        <mu2>0.2</mu2>
        <selfCollide>true</selfCollide>
    </gazebo>
    <gazebo reference="Spur_Gear__24_teeth___1__1">
        <material>Gazebo/Silver</material>
        <mu1>0.2</mu1>
        <mu2>0.2</mu2>
        <selfCollide>true</selfCollide>
    </gazebo>
    
    <link name="world" />
    <link name="base_link">
        <inertial>
            <origin rpy="0 0 0" xyz="3.957301377503479e-05 5.550169171063192e-09 0.0412767136677171" />
            <mass value="2.066513090661844" />
            <inertia ixx="0.006011" ixy="-0.0" ixz="-2e-06" iyy="0.006018" iyz="-0.0" izz="0.009572" />
        </inertial>
        <visual>
            <origin rpy="0 0 0" xyz="0 0 0" />
            <geometry>
                <mesh filename="package://cooking_robot/meshes/base_link.stl" scale="0.001 0.001 0.001" />
            </geometry>
            <material name="silver" />
        </visual>
        <collision>
            <origin rpy="0 0 0" xyz="0 0 0" />
            <geometry>
                <mesh filename="package://cooking_robot/meshes/base_link.stl" scale="0.001 0.001 0.001" />
            </geometry>
        </collision>
    </link>
    <joint name="j0" type="fixed">
        <parent link="world" />
        <child link="base_link" />
        <origin rpy="0.0 0.0 0.0" xyz="0.0 0.0 0.0" />
    </joint>
    <link name="link1_1">
        <inertial>
            <origin rpy="0 0 0" xyz="0.0230637786360918 0.001341583374922287 0.046898108796872714" />
            <mass value="5.742113360427433" />
            <inertia ixx="0.009895" ixy="-0.000482" ixz="-0.005786" iyy="0.017173" iyz="-0.000382" izz="0.013403" />
        </inertial>
        <visual>
            <origin rpy="0 0 0" xyz="-0.0 -0.0 -0.07" />
            <geometry>
                <mesh filename="package://cooking_robot/meshes/link1_1.stl" scale="0.001 0.001 0.001" />
            </geometry>
            <material name="silver" />
        </visual>
        <collision>
            <origin rpy="0 0 0" xyz="-0.0 -0.0 -0.07" />
            <geometry>
                <mesh filename="package://cooking_robot/meshes/link1_1.stl" scale="0.001 0.001 0.001" />
            </geometry>
        </collision>
    </link>
    <link name="link2_1">
        <inertial>
            <origin rpy="0 0 0" xyz="0.08046108742370087 0.03265671734962108 -2.2244900366175102e-11" />
            <mass value="4.349837143782598" />
            <inertia ixx="0.002088" ixy="0.000167" ixz="-0.0" iyy="0.025024" iyz="0.0" izz="0.024204" />
        </inertial>
        <visual>
            <origin rpy="0 0 0" xyz="-0.09 -0.015 -0.17" />
            <geometry>
                <mesh filename="package://cooking_robot/meshes/link2_1.stl" scale="0.001 0.001 0.001" />
            </geometry>
            <material name="silver" />
        </visual>
        <collision>
            <origin rpy="0 0 0" xyz="-0.09 -0.015 -0.17" />
            <geometry>
                <mesh filename="package://cooking_robot/meshes/link2_1.stl" scale="0.001 0.001 0.001" />
            </geometry>
        </collision>
    </link>
    <link name="link3-2_joint_1">
        <inertial>
            <origin rpy="0 0 0" xyz="-5.774756728360586e-08 -0.04520965854239076 0.0029520539853202243" />
            <mass value="0.48926159770428396" />
            <inertia ixx="0.0005" ixy="0.0" ixz="-0.0" iyy="0.000169" iyz="2e-06" izz="0.000447" />
        </inertial>
        <visual>
            <origin rpy="0 0 0" xyz="-0.29 -0.034 -0.17" />
            <geometry>
                <mesh filename="package://cooking_robot/meshes/link3-2_joint_1.stl" scale="0.001 0.001 0.001" />
            </geometry>
            <material name="silver" />
        </visual>
        <collision>
            <origin rpy="0 0 0" xyz="-0.29 -0.034 -0.17" />
            <geometry>
                <mesh filename="package://cooking_robot/meshes/link3-2_joint_1.stl" scale="0.001 0.001 0.001" />
            </geometry>
        </collision>
    </link>
    <link name="link3_1">
        <inertial>
            <origin rpy="0 0 0" xyz="2.4722203617599803e-08 -0.0005180384055503261 0.06152943396730581" />
            <mass value="1.241116625279245" />
            <inertia ixx="0.002432" ixy="0.0" ixz="-0.0" iyy="0.001722" iyz="3e-05" izz="0.001103" />
        </inertial>
        <visual>
            <origin rpy="0 0 0" xyz="-0.29 0.0135 -0.195" />
            <geometry>
                <mesh filename="package://cooking_robot/meshes/link3_1.stl" scale="0.001 0.001 0.001" />
            </geometry>
            <material name="silver" />
        </visual>
        <collision>
            <origin rpy="0 0 0" xyz="-0.29 0.0135 -0.195" />
            <geometry>
                <mesh filename="package://cooking_robot/meshes/link3_1.stl" scale="0.001 0.001 0.001" />
            </geometry>
        </collision>
    </link>
    <link name="gripper_joint1_1">
        <inertial>
            <origin rpy="0 0 0" xyz="-2.1296181484942167e-10 0.04520965864214052 0.002952063965921292" />
            <mass value="0.4892591904426007" />
            <inertia ixx="0.0005" ixy="0.0" ixz="0.0" iyy="0.000169" iyz="-2e-06" izz="0.000447" />
        </inertial>
        <visual>
            <origin rpy="0 0 0" xyz="-0.29 0.0595 -0.3125" />
            <geometry>
                <mesh filename="package://cooking_robot/meshes/gripper_joint1_1.stl" scale="0.001 0.001 0.001" />
            </geometry>
            <material name="silver" />
        </visual>
        <collision>
            <origin rpy="0 0 0" xyz="-0.29 0.0595 -0.3125" />
            <geometry>
                <mesh filename="package://cooking_robot/meshes/gripper_joint1_1.stl" scale="0.001 0.001 0.001" />
            </geometry>
        </collision>
    </link>
    <link name="link4_1">
        <inertial>
            <origin rpy="0 0 0" xyz="0.00018388764296389803 0.00027077966008015597 0.025509584507645178" />
            <mass value="0.6801945828664837" />
            <inertia ixx="0.000469" ixy="0.0" ixz="0.0" iyy="0.000457" iyz="0.0" izz="0.000272" />
        </inertial>
        <visual>
            <origin rpy="0 0 0" xyz="-0.29 0.012 -0.3375" />
            <geometry>
                <mesh filename="package://cooking_robot/meshes/link4_1.stl" scale="0.001 0.001 0.001" />
            </geometry>
            <material name="silver" />
        </visual>
        <collision>
            <origin rpy="0 0 0" xyz="-0.29 0.012 -0.3375" />
            <geometry>
                <mesh filename="package://cooking_robot/meshes/link4_1.stl" scale="0.001 0.001 0.001" />
            </geometry>
        </collision>
    </link>
    <link name="Spur_Gear__24_teeth___1__1">
        <inertial>
            <origin rpy="0 0 0" xyz="-0.010000185471326528 -0.0027254969628815826 0.030042323969180884" />
            <mass value="0.19629204650966112" />
            <inertia ixx="0.000182" ixy="0.0" ixz="0.0" iyy="0.000182" iyz="1.9e-05" izz="1.4e-05" />
        </inertial>
        <visual>
            <origin rpy="0 0 0" xyz="-0.30018 -0.001765 -0.4125" />
            <geometry>
                <mesh filename="package://cooking_robot/meshes/Spur_Gear__24_teeth___1__1.stl" scale="0.001 0.001 0.001" />
            </geometry>
            <material name="silver" />
        </visual>
        <collision>
            <origin rpy="0 0 0" xyz="-0.30018 -0.001765 -0.4125" />
            <geometry>
                <mesh filename="package://cooking_robot/meshes/Spur_Gear__24_teeth___1__1.stl" scale="0.001 0.001 0.001" />
            </geometry>
        </collision>
    </link>
    <link name="Spur_Gear__24_teeth__1">
        <inertial>
            <origin rpy="0 0 0" xyz="-0.010000185471326528 0.0027270129816117927 0.03010843991676121" />
            <mass value="0.19647451990768114" />
            <inertia ixx="0.000183" ixy="0.0" ixz="0.0" iyy="0.000182" iyz="-1.9e-05" izz="1.4e-05" />
        </inertial>
        <visual>
            <origin rpy="0 0 0" xyz="-0.30018 0.025235 -0.4125" />
            <geometry>
                <mesh filename="package://cooking_robot/meshes/Spur_Gear__24_teeth__1.stl" scale="0.001 0.001 0.001" />
            </geometry>
            <material name="silver" />
        </visual>
        <collision>
            <origin rpy="0 0 0" xyz="-0.30018 0.025235 -0.4125" />
            <geometry>
                <mesh filename="package://cooking_robot/meshes/Spur_Gear__24_teeth__1.stl" scale="0.001 0.001 0.001" />
            </geometry>
        </collision>
    </link>
    <joint name="joint_base" type="revolute">
        <origin rpy="0 0 0" xyz="0.0 0.0 0.07" />
        <parent link="base_link" />
        <child link="link1_1" />
        <axis xyz="0.0 0.0 1.0" />
        <limit effort="100" lower="-1.571" upper="1.571" velocity="100" />
    </joint>
    <joint name="joint_link_1" type="revolute">
        <origin rpy="0 0 0" xyz="0.09 0.015 0.1" />
        <parent link="link1_1" />
        <child link="link2_1" />
        <axis xyz="-0.0 1.0 0.0" />
        <limit effort="100" lower="-2.42" upper="0.71" velocity="100" />
    </joint>
    <joint name="joint_link_2" type="revolute">
        <origin rpy="0 0 0" xyz="0.2 0.019 0.0" />
        <parent link="link2_1" />
        <child link="link3-2_joint_1" />
        <axis xyz="0.0 1.0 0.0" />
        <limit effort="100" lower="-1.0" upper="4.0" velocity="100" />
    </joint>
    <joint name="joint_link_3" type="revolute">
        <origin rpy="0 0 0" xyz="0.0 -0.0475 0.025" />
        <parent link="link3-2_joint_1" />
        <child link="link3_1" />
        <axis xyz="0.0 0.0 -1.0" />
        <limit effort="100" lower="-1.571" upper="1.571" velocity="100" />
    </joint>
    <joint name="joint_link_4" type="revolute">
        <origin rpy="0 0 0" xyz="0.0 -0.046 0.1175" />
        <parent link="link3_1" />
        <child link="gripper_joint1_1" />
        <axis xyz="-0.0 1.0 0.0" />
        <limit effort="100" lower="-1.571" upper="1.571" velocity="100" />
    </joint>
    <joint name="joint_gripper" type="revolute">
        <origin rpy="0 0 0" xyz="0.0 0.0475 0.025" />
        <parent link="gripper_joint1_1" />
        <child link="link4_1" />
        <axis xyz="0.0 0.0 -1.0" />
        <limit effort="100" lower="-1.571" upper="1.571" velocity="100" />
    </joint>
    <joint name="joint_gripper_left" type="revolute">
        <origin rpy="0 0 0" xyz="0.01018 0.013765 0.075" />
        <parent link="link4_1" />
        <child link="Spur_Gear__24_teeth___1__1" />
        <axis xyz="1.0 -0.0 0.0" />
        <limit effort="20" lower="-0.68" upper="0" velocity="100" />
        <!-- <dynamics damping="1" friction="1"/> -->
    </joint>
    <joint name="joint_gripper_right" type="revolute">
        <origin rpy="0 0 0" xyz="0.01018 -0.013235 0.075" />
        <parent link="link4_1" />
        <child link="Spur_Gear__24_teeth__1" />
        <axis xyz="1.0 -0.0 0.0" />
        <limit effort="20" lower="0" upper="0.68" velocity="100" />
        <!-- <dynamics damping="1" friction="1"/> -->
        <!-- <mimic joint= 'joint_gripper_left' multiplier='-1' offset='0'/> -->
        
    </joint>
    
</robot>



